<?xml version="1.0"?>
<robot xmlns:xacro="http://ros.org/wiki/xacro" name="SoftHand">

<xacro:if value="${BIGMAN_FIXED_HANDS}">

<xacro:property name="a" value="0.1" />
<xacro:property name="b" value="0.06" />
<xacro:property name="c" value="0.14" />

<!-- For the hand we use the inertia of a parallelepiped -->

<!-- LINKS -->
<link name="RSoftHand"/>

<link name="RSoftHandLink">
    <inertial>
      <origin xyz="0 0 -0.17" rpy="0 0 0"/>
      <mass value="1.2"/>
      <inertia ixx="${1.2*(b*b+c*c)/12.0}"  ixy="0"  ixz="0" iyy="${1.2*(a*a+c*c)/12.0}" iyz="0" izz="${1.2*(a*a+b*b)/12.0}" />
    </inertial>
    <visual>
      <origin xyz="0.0 0.0 0.0" rpy="0.0 0.0 0.0"/>
      <geometry name="RSoftHandLink_visual">
        <mesh filename="package://bigman_urdf/meshes/SoftHandOpen.STL" scale="0.001 0.001 0.001" />
      </geometry>
      <material name="grey"/>
   </visual>
   <collision>
      <origin xyz="0.0 0.0 0.0" rpy="0.0 0.0 0.0"/>
      <geometry name="RSoftHandLink_collision">
        <mesh filename="package://bigman_urdf/meshes/simple/SoftHandOpen.STL" scale="0.001 0.001 0.001" />
      </geometry>
   </collision>
  </link>

  <link name="LSoftHand"/>

  <link name="LSoftHandLink">
    <inertial>
      <origin xyz="0 0 -0.17" rpy="0 0 0"/>
      <mass value="1.2"/>
      <inertia ixx="${1.2*(b*b+c*c)/12.0}"  ixy="0"  ixz="0" iyy="${1.2*(a*a+c*c)/12.0}" iyz="0" izz="${1.2*(a*a+b*b)/12.0}" />
    </inertial>
    <visual>
      <origin xyz="0.0 0.0 0.0" rpy="0.0 0.0 0.0"/>
      <geometry name="LSoftHandLink_visual">
        <mesh filename="package://bigman_urdf/meshes/SoftHandOpen.STL" scale="0.001 -0.001 0.001" />
      </geometry>
      <material name="grey"/>
   </visual>
   <collision>
     <origin xyz="0.0 0.0 0.0" rpy="0.0 0.0 0.0"/>
      <geometry name="LSoftHandLink_collision">
        <mesh filename="package://bigman_urdf/meshes/simple/SoftHandOpen.STL" scale="0.001 -0.001 0.001" />
      </geometry>
   </collision>
  </link>

<!-- JOINTS -->
  <joint name="r_handj" type="fixed">
        <parent link="RWrMot3"/>
        <child link="RSoftHandLink"/>
        <origin xyz="0 0 0" rpy="0 0 0"/>
  </joint>
  
  <joint name="r_handj2" type="fixed">
        <parent link="RSoftHandLink"/>
        <child link="RSoftHand"/>
        <origin xyz="0 0.0305 -0.21" rpy="0 0 0"/>
  </joint>


  <joint name="l_handj" type="fixed">
        <parent link="LWrMot3"/>
        <child link="LSoftHandLink"/>
        <origin xyz="0 0 0" rpy="0 0 0"/>
  </joint>

  <joint name="l_handj2" type="fixed">
        <parent link="LSoftHandLink"/>
        <child link="LSoftHand"/>
        <origin xyz="0 -0.0305 -0.21" rpy="0 0 0"/>
  </joint>

</xacro:if>

<xacro:unless value="${BIGMAN_FIXED_HANDS}">

<!-- LINKS -->
<!-- ## WRONG NUMBERS FOR... ok lasciamo perde... FIX THEM!! ## -->
  <link name="RSoftHand">
    <inertial>
      <origin xyz="0 0 -0.17" rpy="0 0 0"/>
      <mass value="1.2"/>
      <inertia ixx="${1.2*(b*b+c*c)/12.0}"  ixy="0"  ixz="0" iyy="${1.2*(a*a+c*c)/12.0}" iyz="0" izz="${1.2*(a*a+b*b)/12.0}" />
    </inertial>
    <visual>
     <origin xyz="0 0 0" rpy="0 0 0" />
     <geometry>
        <box size="0.07 0.07 0.07" />
     </geometry>
     <material name="Cyan">
       <color rgba="0 1.0 1.0 1.0"/>
     </material>
   </visual>
   <collision>
     <origin xyz="0 0 0" rpy="0 0 0"/>
     <geometry>
       <box size="0.07 0.07 0.07" />
     </geometry>
   </collision>
  </link>

  <link name="LSoftHand">
    <inertial>
      <origin xyz="0 0 -0.17" rpy="0 0 0"/>
      <mass value="1.2"/>
      <inertia ixx="${1.2*(b*b+c*c)/12.0}"  ixy="0"  ixz="0" iyy="${1.2*(a*a+c*c)/12.0}" iyz="0" izz="${1.2*(a*a+b*b)/12.0}" />
    </inertial>
    <visual>
     <origin xyz="0 0 0" rpy="0 0 0" />
     <geometry>
        <box size="0.07 0.07 0.07" />
     </geometry>
     <material name="Cyan">
       <color rgba="0 1.0 1.0 1.0"/>
     </material>
   </visual>
   <collision>
     <origin xyz="0 0 0" rpy="0 0 0"/>
     <geometry>
       <box size="0.07 0.07 0.07" />
     </geometry>
   </collision>
  </link>

<!-- JOINTS -->
<joint name="r_handj" type="revolute">
        <parent link="RWrMot3"/>
        <child link="RSoftHand"/>
        <origin xyz="0 0 -0.04" rpy="0 0 0"/>
        <axis xyz="1 0 0" />
        <limit velocity="4.0" effort="5" lower="0.0" upper="5.0" />
        <dynamics friction="0" damping="3.0"/>
</joint>

<joint name="l_handj" type="revolute">
        <parent link="LWrMot3"/>
        <child link="LSoftHand"/>
        <origin xyz="0 0 -0.04" rpy="0 0 0"/>
        <axis xyz="-1 0 0" />
        <limit velocity="4.0" effort="5" lower="0" upper="5.0" />
        <dynamics friction="0" damping="3.0"/>
</joint>

</xacro:unless>

</robot>
